Workbook
Name Despesas_Dedutivas: Planilha1!$B$99:$B$107
Name Despesas_Incentivadas: Planilha1!$B$108:$B$114
Name Rendimentos_Exclusivos: Planilha1!$B$91:$B$96
Name Rendimentos_Isentos: Planilha1!$B$81:$B$90
Name Rendimentos_Tributaveis: Planilha1!$B$74:$B$80

Sheet Perfil
C3: 1. DADOS DO TITULAR (Cadastro)
E4: preencha as partes indicadas com suas informações
L7: NOME COMPLETO | M7: Lucas Bernardo
L8: CPF | M8: 123456789
L9: DATA DE NASCIMENTO | M9: 38401
L10: TÍTULO DE ELEITOR
L11: OCUPAÇÃO PRINCIPAL (NATUREZA DA OCUPAÇÃO) | M11: Empregado de empresa do setor privado
L12: ENDEREÇO COMPLETO | M12: Rua dos Cocais - 113
L13: CEP | M13: 30570670
L14: BAIRRO
L15: ESTADO | M15: Minas Gerais
L16: CIDADE | M16: Diamantina
L17: CELULAR | M17: 338876598
L18: TELEFONE | M18: -
L19: HOUVE MUDANÇA DE ENDEREÇO DESDE A ÚLTIMA DECLARAÇÃO? | M19: SIM
L20: EMAIL
L21: DEPENDENTES & ALIMENTADOS | M21: SIM
L22: QUANTIDADE | M22: 0
E25: 2. DEPENDENTES E ALIMENTANDOS
E26: =IF(M22>0,"preencha as partes indicadas com suas informações ","")
E29: =IF($M$22=1,"1º DEPENDENTES","") | L29: =IF(M22=1,"TIPO","")
L30: =IF($M$22=1,"GRAU DE PARENTESCO (FILHO, CÔNJUGE, PAIS, ETC.)","")
L31: =IF($M$22=1,"NOME COMPLETO","")
L32: =IF($M$22=1,"CPF (OBRIGATÓRIO PARA TODAS AS IDADES)","")
L33: =IF($M$22=1,"DATA DE NASCIMENTO","")

Sheet Movimentações
C3: 3. RENDIMENTO (TRIBUTAVEIS,ISENSTOS e EXCLUSIVOS)
E4: preencha as partes indicadas com suas informações de rendimento
D6: DATA | E6: TIPO DE RENDIMENTO | F6: DESCRIÇÂO | G6: CNPJ/CPF | H6: VALOR | I6: DATA | J6: TIPO DE RENDIMENTO3 | K6: DESCRIÇÂO2 | L6: CNPJ/CPF2 | M6: VALOR2 | O6: TRIBUTAVEIS | P6: TOTAL
D7: 38405 | E7: Outros | H7: 27 | I7: 25 | O7: {=SUMPRODUCT(COUNTIF(Rendimentos_Tributaveis, $E$6:$E$23)) + SUMPRODUCT(COUNTIF(Rendimentos_Tributaveis, $J$6:$J$23))} -> 1 | P7: {=SUMPRODUCT(SUMIF($E$6:$E$23, Rendimentos_Tributaveis, $H$6:$H$23)) + SUMPRODUCT(SUMIF($J$6:$J$23, Rendimentos_Tributaveis, $M$6:$M$23))} -> 100
D8: 38406 | E8: Pró-labore | H8: 100 | I8: 38423
D9: 38407 | E9: Rendimentos de Poupança, LCI, LCA, CRI e CRA | H9: 15 | I9: 38424
D10: 38408 | I10: 38425 | O10: ISENTO | P10: TOTAL
D11: 38409 | I11: 38426 | O11: {=SUMPRODUCT(COUNTIF(Rendimentos_Isentos, $E$6:$E$23)) + SUMPRODUCT(COUNTIF(Rendimentos_Isentos, $J$6:$J$23))} -> 1 | P11: {=SUMPRODUCT(SUMIF($E$6:$E$23, Rendimentos_Isentos, $H$6:$H$23)) + SUMPRODUCT(SUMIF($J$6:$J$23, Rendimentos_Isentos, $M$6:$M$23))} -> 15
D12: 38410 | I12: 38427
D13: 38411 | I13: 38428
D14: 38412 | I14: 38429 | O14: EXCLUSIVO | P14: TOTAL
D15: 38413 | I15: 38430 | O15: {=SUMPRODUCT(COUNTIF(Rendimentos_Exclusivos, $E$6:$E$23)) + SUMPRODUCT(COUNTIF(Rendimentos_Exclusivos, $J$6:$J$23))} -> 0 | P15: {=SUMPRODUCT(SUMIF($E$6:$E$23, Rendimentos_Isentos, $H$6:$H$23)) + SUMPRODUCT(SUMIF($J$6:$J$23, Rendimentos_Isentos, $M$6:$M$23))} -> 15
D16: 38414 | I16: 38431
D17: 38415 | I17: 38432
D18: 38416 | I18: 38433 | O18: OUTROS | P18: TOTAL
D19: 38417 | I19: 38434 | O19: {=SUMPRODUCT(COUNTIF(Planilha1!B97, $E$6:$E$23)) + SUMPRODUCT(COUNTIF(Planilha1!B97, $J$6:$J$23))} -> 1 | P19: =SUMPRODUCT(SUMIF($E$6:$E$23, Planilha1!B97, $H$6:$H$23)) + SUMPRODUCT(SUMIF($J$6:$J$23, Planilha1!B97, $M$6:$M$23)) -> 27
D20: 38418 | I20: 38435
D21: 38419 | I21: 38436
D22: 38420 | I22: 38437
D23: 38421 | I23: 38438
E26: 4. DEDUÇÔES (SAIDAS/PAGAMENTOS)
E27: preencha as partes indicadas com suas informações de deduções aprovadas pelo governo, e não com a suas despesas pessoais habituais.
D29: DATA | E29: TIPO DE DESPESA | F29: DESCRIÇÂO | G29: BENEFICIARIO | H29: VALOR | I29: DATA | J29: TIPO DE DESPESA2 | K29: DESCRIÇÂO2 | L29: BENEFICIARIO2 | M29: VALOR4 | O29: DEDUTIVEL | P29: TOTAL
D30: 38405 | E30: Médicos (Consultas e Tratamentos) | H30: 27 | I30: 25 | O30: {=SUMPRODUCT(COUNTIF(Despesas_Dedutivas, $E$29:$E$46)) + SUMPRODUCT(COUNTIF(Despesas_Dedutivas, $J$29:$J$46))} -> 1 | P30: {=SUMPRODUCT(SUMIF($E$29:$E$46, Despesas_Dedutivas, $H$29:$H$46)) + SUMPRODUCT(SUMIF($J$29:$J$46, Despesas_Dedutivas, $M$29:$M$46))} -> 27 | Q30: =IF(R23=1,"TIPO","")
D31: 38406 | E31: Incentivo à Cultura (Lei Rouanet) | H31: 100 | I31: 38423 | Q31: =IF($R$23=1,"GRAU DE PARENTESCO (FILHO, CÔNJUGE, PAIS, ETC.)","")
D32: 38407 | E32: Outros | H32: 50 | I32: 38424 | Q32: =IF($R$23=1,"NOME COMPLETO","")
D33: 38408 | I33: 38425 | O33: INCENTIVADO | P33: TOTAL | Q33: =IF($R$23=1,"CPF (OBRIGATÓRIO PARA TODAS AS IDADES)","")
D34: 38409 | I34: 38426 | O34: {=SUMPRODUCT(COUNTIF(Despesas_Incentivadas, $E$29:$E$46)) + SUMPRODUCT(COUNTIF(Despesas_Incentivadas, $J$29:$J$46))} -> 1 | P34: {=SUMPRODUCT(SUMIF($E$29:$E$46, Despesas_Incentivadas, $H$29:$H$46)) + SUMPRODUCT(SUMIF($J$29:$J$46, Despesas_Incentivadas, $M$29:$M$46))} -> 100 | Q34: =IF($R$23=1,"DATA DE NASCIMENTO","")
D35: 38410 | I35: 38427
D36: 38411 | I36: 38428
D37: 38412 | I37: 38429 | O37: OUTROS | P37: TOTAL
D38: 38413 | I38: 38430 | O38: {=SUMPRODUCT(COUNTIF(Planilha1!B115, $E$29:$E$46)) + SUMPRODUCT(COUNTIF(Planilha1!B115, $J$29:$J$46))} -> 1 | P38: =SUMPRODUCT(SUMIF($E$29:$E$46, Planilha1!B115, $H$29:$H$46)) + SUMPRODUCT(SUMIF($J$29:$J$46, Planilha1!B115, $M$29:$M$46)) -> 50
D39: 38414 | I39: 38431
D40: 38415 | I40: 38432
D41: 38416 | I41: 38433
D42: 38417 | I42: 38434
D43: 38418 | I43: 38435
D44: 38419 | I44: 38436
D45: 38420 | I45: 38437
D46: 38421 | I46: 38438

Sheet PT_DV
C3: 5. PATRIMONIOS E DIVIDAS
D5: TOTAL ANO PASSADO | E5: =SUM(E9,H9,E14,H14,E19,H19) -> 0 | G5: TOTAL ANO ATUAL | H5: =SUM(E10,H10,E15,H15,H20,E20) -> 0
D7: TIPO DE BEM | G7: TIPO DE BEM
D8: DESCRIÇÂO | G8: DESCRIÇÂO
D9: SALDO INICIAL (xx/xx/xxxx) | G9: SALDO INICIAL (xx/xx/xxxx)
D10: SALDO FINAL (xx/xx/xxxx) | G10: SALDO FINAL (xx/xx/xxxx)
D12: TIPO DE BEM | G12: TIPO DE BEM
D13: DESCRIÇÂO | G13: DESCRIÇÂO
D14: SALDO INICIAL (xx/xx/xxxx) | G14: SALDO INICIAL (xx/xx/xxxx)
D15: SALDO FINAL (xx/xx/xxxx) | G15: SALDO FINAL (xx/xx/xxxx)
D17: TIPO DE BEM | G17: TIPO DE BEM
D18: DESCRIÇÂO | G18: DESCRIÇÂO
D19: SALDO INICIAL (xx/xx/xxxx) | G19: SALDO INICIAL (xx/xx/xxxx)
D20: SALDO FINAL (xx/xx/xxxx) | G20: SALDO FINAL (xx/xx/xxxx)
E29: =IF($M$22=1,"1º DEPENDENTES","") | L29: =IF(M22=1,"TIPO","")
L30: =IF($M$22=1,"GRAU DE PARENTESCO (FILHO, CÔNJUGE, PAIS, ETC.)","")
L31: =IF($M$22=1,"NOME COMPLETO","")
L32: =IF($M$22=1,"CPF (OBRIGATÓRIO PARA TODAS AS IDADES)","")
L33: =IF($M$22=1,"DATA DE NASCIMENTO","")

Sheet D_BC
C3: DADOS BANCARIOS
F7: BANCO 1º
F8: Tipo de Conta: | K8: Conta Poupança
F9: Banco: | K9: 102 - XP Investimentos CCTVM S.A. | R9: TOTAL | S9: =SUM(K13,K21) -> 162000
F10: Agência:
F11: Número da Conta:
F12: Chave PIX:
F13: VALOR: | K13: 150000
F15: BANCO 2º
F16: Tipo de Conta: | K16: Conta Poupança
F17: Banco: | K17: 102 - XP Investimentos CCTVM S.A.
F18: Agência:
F19: Número da Conta:
F20: Chave PIX:
F21: VALOR: | K21: 12000
E29: =IF($M$22=1,"1º DEPENDENTES","") | L29: =IF(M22=1,"TIPO","")
F30: Python | L30: =IF($M$22=1,"GRAU DE PARENTESCO (FILHO, CÔNJUGE, PAIS, ETC.)","")
F63: Tipo de Conta: Crie uma lista suspensa com as opções (Conta Corrente, Conta Poupança, Conta de Pagamento).
F64: Banco: O código e o nome do banco (Ex: 001 - Banco do Brasil, 341 - Itaú, 260 - Nubank).
F65: Agência: Apenas os números, geralmente sem o dígito verificador.
F66: Número da Conta: O número completo junto com o dígito verificador (DV).
F67: Chave PIX: Uma opção cada vez mais usada para receber a restituição mais rápido.

Sheet Planilha1
B1: BANCOS | D1: OCUPAÇÕES
B2: 1 - Banco do Brasil | D2: Empregado de empresa do setor privado
B3: 102 - XP Investimentos CCTVM S.A. | D3: Trabalhador de instituição pública (Federal, Estadual ou Municipal)
B4: 104 - Caixa Econômica Federal | D4: Empregado de organizações não governamentais (ONGs)
B5: 119 - Banco Western Union do Brasil | D5: Empregado de empresas públicas e sociedades de economia mista
B6: 184 - Banco Itaú BBA S.A. | D6: Militar (Aeronáutica, Exército, Marinha ou Polícias)
B7: 197 - Stone Pagamentos | D7: Profissional liberal ou autônomo sem vínculo de emprego
B8: 208 - Banco BTG Pactual | D8: Proprietário de empresa ou de firma individual
B9: 212 - Banco Original | D9: Aposentado, militar da reserva ou pensionista de previdência
B10: 218 - Banco Bonsucesso | D10: Beneficiário de pensão alimentícia judicial
B11: 229 - Banco Cruzeiro do Sul | D11: Bolsista
B12: 237 - Banco Bradesco | D12: Desempregado ou não aplicável
B13: 24 - Banco de Pernambuco | D13: Outras ocupações
B14: 241 - Banco Clássico | D14: 66
B15: 250 - Banco de Crédito e Varejo (BCV) | D15: ESTADOS
B16: 260 - Nubank | D16: Acre(AC)
B17: 29 - Banco do Estado do Rio de Janeiro | D17: Alagoas(AL)
B18: 290 - PagBank | D18: Amapá(AP)
B19: 3 - Banco da Amazônia | D19: Amazonas(AM)
B20: 33 - Banco Santander | D20: Bahia(BA)
B21: 336 - C6 Bank | D21: Ceará(CE)
B22: 341 - Itaú Unibanco | D22: DistritoFederal(DF)
B23: 37 - Banco do Estado do Pará | D23: EspíritoSanto(ES)
B24: 376 - Banco JPMorgan S.A. | D24: Goiás(GO)
B25: 380 - PicPay | D25: Maranhão(MA)
B26: 4 - Banco do Nordeste do Brasil | D26: MatoGrosso(MT)
... B42: 72 - Banco Rural Mais | D42: Tocantins(TO).
B43: 734 - Banco Gerdau
B44: 735 - Banco Neon
B45: 74 - Banco J. Safra
B46: 746 - Banco Modal
B47: 748 - Banco Cooperativo Sicredi S.A.
B48: 749 - Banco Simples
B49: 77 - Banco Inter
B50: 79 - Banco JBS
B51: 82 - Banco Topázio
B53: BENIFICIARIOS | C53: DEPENDENTE
B54: =IF(Perfil!M7<>"",Perfil!M7,"") -> Lucas Bernardo | C54: =IF(B54<>"","TITULAR","") -> TITULAR
B55: =IF(Perfil!M31<>"",Perfil!M31,"") | C55: =IF(B55<>"","DEPENDENTE 1","")
A74: Rendimentos Tributáveis | B74: Salários e Vencimentos
...
